<mujoco model="husky_robot">
  <compiler angle="radian" meshdir="./assets/" autolimits="true"/>
  <!-- Default -->
  <default>
    <joint limited="false" armature="0.01" /> <!-- rolling joint -->
    <equality solref="0.0002 1" solimp="0.99 0.99 0.0001" />
  </default>
  <asset>
    <mesh name="base_link" file="base_link.stl"/>
    <mesh name="wheel" file="wheel.stl"/>
    <mesh name="top_plate" file="top_plate.stl"/>
    <mesh name="user_rail" file="user_rail.stl"/>
    <mesh name="bumper" file="bumper.stl"/>
    <mesh name="large_top_plate" file="large_top_plate.obj"/>
    <!-- <mesh name="large_top_plate_collision" file="large_top_plate_collision.stl" /> -->
    <!-- <texture type="skybox" builtin="gradient" rgb1="0.3 0.5 0.7" rgb2="0 0 0" width="512" height="3072"/>
    <texture type="2d" name="groundplane" builtin="checker" mark="edge" rgb1="0.2 0.3 0.4" rgb2="0.1 0.2 0.3" markrgb="0.8 0.8 0.8" width="300" height="300"/>
    <material name="groundplane" texture="groundplane" texuniform="true" texrepeat="5 5" reflectance="0.2"/> -->
  </asset>
  <worldbody>
    <light pos="0 0 1.5" dir="0 0 -1" directional="true"/>
    <!-- <geom name="floor" size="0 0 0.05" type="plane" material="groundplane"/> -->
    <body name="base_husky" pos="0 0 0.1" euler="0 0 0" >
      <!-- Originally the mass of base_husky was "mass="2.637" -->
      <inertial pos="0 0 0" quat="0.5 0.5 -0.5 0.5" mass="100" diaginertia="0.04411 0.02467 0.02467"/>
      <joint type="free" name="base_husky_joint" />
      <geom pos="0 0 0.14493" type="mesh" contype="0" conaffinity="1" group="1" density="0" rgba="0.1 0.1 0.1 1" mesh="base_link"/>
      <geom pos="0 0 0.14493" type="mesh" contype="0" conaffinity="1" group="1" density="0" rgba="0.8 0.8 0 1" mesh="top_plate"/>
      <geom pos="0.272 0 0.38993" type="mesh" contype="0" conaffinity="1" group="1" density="0" rgba="0.3 0.3 0.3 1" mesh="user_rail"/>
      <geom pos="0.48 0 0.23593" type="mesh" contype="0" conaffinity="1" group="1" density="0" rgba="0.3 0.3 0.3 1" mesh="bumper"/>
      <geom pos="-0.48 0 0.23593" quat="1.32679e-06 0 0 1" type="mesh" contype="0" conaffinity="1" group="1" density="0" rgba="0.3 0.3 0.3 1" mesh="bumper"/>
      <geom pos="0.08 0 0.38993" type="mesh" contype="0" conaffinity="1" group="1" density="0" rgba="0.1 0.1 0.1 1" mesh="large_top_plate"/>
      <body name="front_left_wheel_link" pos="0.256 0.2854 0.17775" gravcomp="0" euler="0 0 3.14">
        <inertial pos="0 0 0" quat="0.5 0.5 -0.5 0.5" mass="2.637" diaginertia="0.04411 0.02467 0.02467"/>
        <joint name="front_left_wheel" pos="0 0 0" axis="0 1 0"/>
        <geom type="mesh" contype="0" conaffinity="1" group="1" density="0" rgba="0.3 0.3 0.3 1" mesh="wheel"/>
        <!-- <geom size="0.17775 0.05715" quat="0.707107 0.707106 0 0" type="cylinder" rgba="0.3 0.3 0.3 1"/> -->
      </body>
      <body name="front_right_wheel_link" pos="0.256 -0.2854 0.17775" gravcomp="0" euler="0 0 3.14">
        <inertial pos="0 0 0" quat="0.5 0.5 -0.5 0.5" mass="2.637" diaginertia="0.04411 0.02467 0.02467"/>
        <joint name="front_right_wheel" pos="0 0 0" axis="0 1 0"/>
        <geom type="mesh" contype="0" conaffinity="1" group="1" density="0" rgba="0.3 0.3 0.3 1" mesh="wheel"/>
        <!-- <geom size="0.17775 0.05715" quat="0.707107 0.707106 0 0" type="cylinder" rgba="0.3 0.3 0.3 1"/> -->
      </body>
      <body name="rear_left_wheel_link" pos="-0.256 0.2854 0.17775" gravcomp="0" euler="0 0 3.14">
        <inertial pos="0 0 0" quat="0.5 0.5 -0.5 0.5" mass="2.637" diaginertia="0.04411 0.02467 0.02467"/>
        <joint name="rear_left_wheel" pos="0 0 0" axis="0 1 0"/>
        <geom type="mesh" contype="0" conaffinity="1" group="1" density="0" rgba="0.3 0.3 0.3 1" mesh="wheel"/>
        <!-- <geom size="0.17775 0.05715" quat="0.707107 0.707106 0 0" type="cylinder" rgba="0.3 0.3 0.3 1"/> -->
      </body>
      <body name="rear_right_wheel_link" pos="-0.256 -0.2854 0.17775" gravcomp="0" euler="0 0 3.14">
        <inertial pos="0 0 0" quat="0.5 0.5 -0.5 0.5" mass="2.637" diaginertia="0.04411 0.02467 0.02467"/>
        <joint name="rear_right_wheel" pos="0 0 0" axis="0 1 0"/>
        <geom type="mesh" contype="0" conaffinity="1" group="1" density="0" rgba="0.3 0.3 0.3 1" mesh="wheel"/>
        <!-- <geom size="0.17775 0.05715" quat="0.707107 0.707106 0 0" type="cylinder" rgba="0.3 0.3 0.3 1"/> -->
      </body>
      <camera name="cam" pos="0 0 0.5" quat="0.5 0.5 -0.5 -0.5" fovy="40" resolution="640 480"/>  
    </body>
  </worldbody>
  <actuator>
    <velocity name="front_left_actuator" ctrllimited="true" ctrlrange="-100.0 100.0" gear="-1"
      kv="10" joint="front_left_wheel" />
    <velocity name="front_right_actuator" ctrllimited="true" ctrlrange="-100.0 100.0" gear="-1"
      kv="10" joint="front_right_wheel" />
    <velocity name="rear_left_actuator" ctrllimited="true" ctrlrange="-100.0 100.0" gear="-1"
      kv="10" joint="rear_left_wheel" />
    <velocity name="rear_right_actuator" ctrllimited="true" ctrlrange="-100.0 100.0" gear="-1"
      kv="10" joint="rear_right_wheel" />
  </actuator>
</mujoco>
