<mujoco model="tidybot_with_hand">
  <compiler angle="radian" meshdir="assets"/>

  <option integrator="implicitfast"/>
  <option cone="elliptic" impratio="10"/>

  <default>
    <default class="base">
      <default class="base/visual">
        <geom type="mesh" contype="0" conaffinity="0" group="2"/>
      </default>
      <default class="base/collision">
        <geom type="mesh" group="3"/>
      </default>
    </default>
        
    <default class="gen3">
      <default class="gen3/visual">
        <geom type="mesh" contype="0" conaffinity="0" group="2" rgba="0.75294 0.75294 0.75294 1"/>
      </default>
      <default class="gen3/collision">
        <geom type="mesh" group="3"/>
      </default>
      <default class="large_actuator">
        <position kp="10000" kv="500" forcerange="-5000 5000"/>
      </default>
      <default class="small_actuator">
        <position kp="5000" kv="200" forcerange="-5000 5000"/>
      </default>
    </default>

    <site size="0.001" rgba="0.5 0.5 0.5 0.3" group="4"/>

    <default class="rangefinder">
      <site size="0.01" pos="0.24 0 0" rgba="1 0 0 1" group="5"/>
    </default>

    <default class="right_hand">
      <mesh scale="0.001 0.001 0.001"/>
      <joint axis="1 0 0" damping="0.05" armature="0.0002" frictionloss="0.01"/>
      <position forcerange="-1 1"/>

      <default class="wrist">
        <joint damping="0.5"/>
        <default class="wrist_y">
          <joint axis="0 1 0" range="-0.523599 0.174533"/>
          <position kp="10" ctrlrange="-0.523599 0.174533" forcerange="-10 10"/>
        </default>
        <default class="wrist_x">
          <joint range="-0.698132 0.488692"/>
          <position kp="8" ctrlrange="-0.698132 0.488692" forcerange="-5 5"/>
        </default>
      </default>

      <default class="thumb">
        <default class="thbase">
          <joint axis="0 0 -1" range="-1.0472 1.0472"/>
          <position kp="0.4" ctrlrange="-1.0472 1.0472" forcerange="-3 3"/>
        </default>
        <default class="thproximal">
          <joint range="0 1.22173"/>
          <position ctrlrange="0 1.22173" forcerange="-2 2"/>
        </default>
        <default class="thhub">
          <joint range="-0.20944 0.20944"/>
          <position kp="0.5" ctrlrange="-0.20944 0.20944"/>
        </default>
        <default class="thmiddle">
          <joint axis="0 -1 0" range="-0.698132 0.698132"/>
          <position kp="1.5" ctrlrange="-0.698132 0.698132"/>
        </default>
        <default class="thdistal">
          <joint range="-0.261799 1.5708"/>
          <position ctrlrange="-0.261799 1.5708"/>
        </default>
      </default>

      <default class="metacarpal">
        <joint axis="0.573576 0 0.819152" range="0 0.785398"/>
        <position ctrlrange="0 0.785398"/>
      </default>
      <default class="knuckle">
        <joint axis="0 -1 0" range="-0.349066 0.349066"/>
        <position ctrlrange="-0.349066 0.349066"/>
      </default>
      <default class="proximal">
        <joint range="-0.261799 1.5708"/>
        <position ctrlrange="-0.261799 1.5708"/>
      </default>
      <default class="middle_distal">
        <joint range="0 1.5708"/>
        <position kp="0.5" ctrlrange="0 3.1415"/>
      </default>

      <default class="plastic">
        <geom solimp="0.5 0.99 0.0001" solref="0.005 1"/>
        <default class="plastic_visual">
          <geom type="mesh" material="black" contype="0" conaffinity="0" group="2"/>
        </default>
        <default class="plastic_collision">
          <geom group="3"/>
        </default>
      </default>
    </default>
  </default>

  <asset>
    <material name="black" rgba="0.11372549 0.11372549 0.10196078 1"/>
    <material name="gray" rgba="0.62745098 0.65098039 0.64705882 1"/>
    <material name="dark_gray" rgba="0.35294118 0.37647059 0.37254902 1"/>
    <mesh file="base/bumper.stl"/>
    <mesh file="base/bottom_plate.stl"/>
    <mesh file="base/body.stl"/>
    <mesh file="base/top_plate.stl"/>
    <mesh file="base/arm_plate.stl"/>

    <mesh name="gen3/base_link" file="gen3/base_link.stl"/>
    <mesh name="shoulder_link" file="gen3/shoulder_link.stl"/>
    <mesh name="half_arm_1_link" file="gen3/half_arm_1_link.stl"/>
    <mesh name="half_arm_2_link" file="gen3/half_arm_2_link.stl"/>
    <mesh name="forearm_link" file="gen3/forearm_link.stl"/>
    <mesh name="spherical_wrist_1_link" file="gen3/spherical_wrist_1_link.stl"/>
    <mesh name="spherical_wrist_2_link" file="gen3/spherical_wrist_2_link.stl"/>
    <mesh name="bracelet_with_vision_link" file="gen3/bracelet_with_vision_link.stl"/>

    <!-- 추가: right_hand asset -->
    <material name="black_hand" specular="0.5" shininess="0.25" rgba="0.16355 0.16355 0.16355 1"/>
    <material name="gray_hand" specular="0.0" shininess="0.25" rgba="0.80848 0.80848 0.80848 1"/>
    <material name="metallic_hand" specular="0" shininess="0.25" rgba="0.9 0.9 0.9 1"/>


    <mesh class="right_hand" file="hand/forearm_0.obj"/>
    <mesh class="right_hand" file="hand/forearm_1.obj"/>
    <mesh class="right_hand" file="hand/forearm_collision.obj"/>
    <mesh class="right_hand" file="hand/wrist.obj"/>
    <mesh class="right_hand" file="hand/palm.obj"/>
    <mesh class="right_hand" file="hand/f_knuckle.obj"/>
    <mesh class="right_hand" file="hand/f_proximal.obj"/>
    <mesh class="right_hand" file="hand/f_middle.obj"/>
    <mesh class="right_hand" file="hand/f_distal_pst.obj"/>
    <mesh class="right_hand" file="hand/lf_metacarpal.obj"/>
    <mesh class="right_hand" file="hand/th_proximal.obj"/>
    <mesh class="right_hand" file="hand/th_middle.obj"/>
    <mesh class="right_hand" file="hand/th_distal_pst.obj"/>

  </asset>

  <worldbody>  
    <camera name="fixed_front"
          pos="1.8 0 0.3" 
          euler="0 1.57 1.57" 
          fovy="55" 
          resolution="640 480"/>
    <body name="base_link">
      <inertial pos="0 0 0.035" mass="60" diaginertia="0.001 0.001 0.001"/>
      <joint name="joint_x" type="slide" axis="1 0 0"/>
      <joint name="joint_y" type="slide" axis="0 1 0"/>
      <joint name="joint_th"/>
      <geom class="base/visual" mesh="bumper" material="black"/>
      <geom class="base/visual" mesh="bottom_plate" material="dark_gray"/>
      <geom class="base/visual" mesh="body" material="gray"/>
      <geom class="base/visual" mesh="top_plate" material="dark_gray"/>
      <geom class="base/visual" mesh="arm_plate" material="gray"/>
      <geom class="base/collision" mesh="bumper"/>
      <geom class="base/collision" mesh="bottom_plate"/>
      <geom class="base/collision" mesh="body"/>
      <geom class="base/collision" mesh="top_plate"/>
      <geom class="base/collision" mesh="arm_plate"/>
      <camera name="base" pos="0.2525 0 0.335" euler="0 -0.7853981634 -1.5707963268" fovy="52.23384539951277"
        resolution="640 360"/>
      <body name="gen3/base_link" pos="0 0 0.335" quat="-1 0 0 0">
        <inertial pos="-0.000648 -0.000166 0.084487" quat="0.999294 0.00139618 -0.0118387 0.035636" mass="1.697"
          diaginertia="0.00462407 0.00449437 0.00207755"/>
        <geom class="gen3/visual" mesh="gen3/base_link"/>
        <geom class="gen3/collision" mesh="gen3/base_link"/>
        <site name="rf_00" class="rangefinder" euler="-1.57080 0.00000  1.57080"/>
        <site name="rf_01" class="rangefinder" euler="-1.57080 0.08727  1.57080"/>
        <site name="rf_02" class="rangefinder" euler="-1.57080 0.17453  1.57080"/>
        <site name="rf_03" class="rangefinder" euler="-1.57080 0.26180  1.57080"/>
        <site name="rf_04" class="rangefinder" euler="-1.57080 0.34907  1.57080"/>
        <site name="rf_05" class="rangefinder" euler="-1.57080 0.43633  1.57080"/>
        <site name="rf_06" class="rangefinder" euler="-1.57080 0.52360  1.57080"/>
        <site name="rf_07" class="rangefinder" euler="-1.57080 0.61087  1.57080"/>
        <site name="rf_08" class="rangefinder" euler="-1.57080 0.69813  1.57080"/>
        <site name="rf_09" class="rangefinder" euler="-1.57080 0.78540  1.57080"/>
        <site name="rf_10" class="rangefinder" euler="-1.57080 0.87266  1.57080"/>
        <site name="rf_11" class="rangefinder" euler="-1.57080 0.95993  1.57080"/>
        <site name="rf_12" class="rangefinder" euler="-1.57080 1.04720  1.57080"/>
        <site name="rf_13" class="rangefinder" euler="-1.57080 1.13446  1.57080"/>
        <site name="rf_14" class="rangefinder" euler="-1.57080 1.22173  1.57080"/>
        <site name="rf_15" class="rangefinder" euler="-1.57080 1.30900  1.57080"/>
        <site name="rf_16" class="rangefinder" euler="-1.57080 1.39626  1.57080"/>
        <site name="rf_17" class="rangefinder" euler="-1.57080 1.48353  1.57080"/>
        <site name="rf_18" class="rangefinder" euler=" 0.00000 1.57080  0.00000"/>
        <site name="rf_19" class="rangefinder" euler=" 1.57080 1.48353 -1.57080"/>
        <site name="rf_20" class="rangefinder" euler=" 1.57080 1.39626 -1.57080"/>
        <site name="rf_21" class="rangefinder" euler=" 1.57080 1.30900 -1.57080"/>
        <site name="rf_22" class="rangefinder" euler=" 1.57080 1.22173 -1.57080"/>
        <site name="rf_23" class="rangefinder" euler=" 1.57080 1.13446 -1.57080"/>
        <site name="rf_24" class="rangefinder" euler=" 1.57080 1.04720 -1.57080"/>
        <site name="rf_25" class="rangefinder" euler=" 1.57080 0.95993 -1.57080"/>
        <site name="rf_26" class="rangefinder" euler=" 1.57080 0.87266 -1.57080"/>
        <site name="rf_27" class="rangefinder" euler=" 1.57080 0.78540 -1.57080"/>
        <site name="rf_28" class="rangefinder" euler=" 1.57080 0.69813 -1.57080"/>
        <site name="rf_29" class="rangefinder" euler=" 1.57080 0.61087 -1.57080"/>
        <site name="rf_30" class="rangefinder" euler=" 1.57080 0.52360 -1.57080"/>
        <site name="rf_31" class="rangefinder" euler=" 1.57080 0.43633 -1.57080"/>
        <site name="rf_32" class="rangefinder" euler=" 1.57080 0.34907 -1.57080"/>
        <site name="rf_33" class="rangefinder" euler=" 1.57080 0.26180 -1.57080"/>
        <site name="rf_34" class="rangefinder" euler=" 1.57080 0.17453 -1.57080"/>
        <site name="rf_35" class="rangefinder" euler=" 1.57080 0.08727 -1.57080"/>
        <site name="rf_36" class="rangefinder" euler=" 1.57080 0.00000 -1.57080"/>
        <body name="shoulder_link" pos="0 0 0.15643" quat="0 1 0 0">
          <inertial pos="-2.3e-05 -0.010364 -0.07336" quat="0.707051 0.0451246 -0.0453544 0.704263" mass="1.3773"
            diaginertia="0.00488868 0.00457 0.00135132"/>
          <joint name="joint_1" range="-3.14159 3.14159"/>
          <geom class="gen3/visual" mesh="shoulder_link"/>
          <geom class="gen3/collision" mesh="shoulder_link"/>
          <body name="half_arm_1_link" pos="0 0.005375 -0.12838" quat="1 1 0 0">
            <inertial pos="-4.4e-05 -0.09958 -0.013278" quat="0.482348 0.516286 -0.516862 0.483366" mass="1.1636"
              diaginertia="0.0113017 0.011088 0.00102532"/>
            <joint name="joint_2" range="-2.24 2.24"/>
            <geom class="gen3/visual" mesh="half_arm_1_link"/>
            <geom class="gen3/collision" mesh="half_arm_1_link"/>
            <body name="half_arm_2_link" pos="0 -0.21038 -0.006375" quat="1 -1 0 0">
              <inertial pos="-4.4e-05 -0.006641 -0.117892" quat="0.706144 0.0213722 -0.0209128 0.707437" mass="1.1636"
                diaginertia="0.0111633 0.010932 0.00100671"/>
              <joint name="joint_3" range="-3.14159 3.14159"/>
              <geom class="gen3/visual" mesh="half_arm_2_link"/>
              <geom class="gen3/collision" mesh="half_arm_2_link"/>
              <body name="forearm_link" pos="0 0.006375 -0.21038" quat="1 1 0 0">
                <inertial pos="-1.8e-05 -0.075478 -0.015006" quat="0.483678 0.515961 -0.515859 0.483455" mass="0.9302"
                  diaginertia="0.00834839 0.008147 0.000598606"/>
                <joint name="joint_4" range="-2.57 2.57"/>
                <geom class="gen3/visual" mesh="forearm_link"/>
                <geom class="gen3/collision" mesh="forearm_link"/>
                <body name="spherical_wrist_1_link" pos="0 -0.20843 -0.006375" quat="1 -1 0 0">
                  <inertial pos="1e-06 -0.009432 -0.063883" quat="0.703558 0.0707492 -0.0707492 0.703558" mass="0.6781"
                    diaginertia="0.00165901 0.001596 0.000346988"/>
                  <joint name="joint_5" range="-3.14159 3.14159"/>
                  <geom class="gen3/visual" mesh="spherical_wrist_1_link"/>
                  <geom class="gen3/collision" mesh="spherical_wrist_1_link"/>
                  <body name="spherical_wrist_2_link" pos="0 0.00017505 -0.10593" quat="1 1 0 0">
                    <inertial pos="1e-06 -0.045483 -0.00965" quat="0.44426 0.550121 -0.550121 0.44426" mass="0.6781"
                      diaginertia="0.00170087 0.001641 0.00035013"/>
                    <joint name="joint_6" range="-2.09 2.09"/>
                    <geom class="gen3/visual" mesh="spherical_wrist_2_link"/>
                    <geom class="gen3/collision" mesh="spherical_wrist_2_link"/>
                    <body name="bracelet_link" pos="0 -0.10593 -0.00017505" quat="1 -1 0 0">
                      <inertial pos="0.000281 0.011402 -0.029798" quat="0.394358 0.596779 -0.577293 0.393789" mass="0.5"
                        diaginertia="0.000657336 0.000587019 0.000320645"/>
                      <joint name="joint_7" range="-3.14159 3.14159"/>
                      <geom class="gen3/visual" mesh="bracelet_with_vision_link"/>
                      <geom class="gen3/collision" mesh="bracelet_with_vision_link"/>

                      <!-- <body name="base" pos="0 0 -0.06149039" quat="0 -1 1 0" childclass="2f85">
                        <inertial mass="0.777441" pos="0 -2.70394e-05 0.0354675" quat="1 -0.00152849 0 0"
                          diaginertia="0.000260285 0.000225381 0.000152708"/>
                        <geom class="2f85/visual" mesh="base" material="2f85/black"/>
                        <geom class="2f85/collision" mesh="base"/>
                      </body> -->

                      <body name="rh_forearm" childclass="right_hand" quat="0 1 0 1">
                        <inertial mass="3" pos="0 0 0.09" diaginertia="0.0138 0.0138 0.00744"/>
                        <geom class="plastic_visual" mesh="forearm_0" material="gray_hand"/>
                        <geom class="plastic_visual" mesh="forearm_1"/>
                        <geom class="plastic_collision" type="mesh" mesh="forearm_collision"/>
                        <geom class="plastic_collision" size="0.035 0.035 0.035" pos="0.01 0.0 0.181" quat="0.380188 0.924909 0 0"
                          type="box"/>
                        <body name="rh_wrist" pos="0.01 0 0.21301" quat="1 0 0 1">
                          <inertial mass="0.1" pos="0 0 0.029" quat="0.5 0.5 0.5 0.5" diaginertia="6.4e-05 4.38e-05 3.5e-05"/>
                          <joint class="wrist_y" name="rh_WRJ2"/>
                          <geom class="plastic_visual" mesh="wrist" material="metallic_hand"/>
                          <geom size="0.0135 0.015" quat="0.499998 0.5 0.5 -0.500002" type="cylinder" class="plastic_collision"/>
                          <geom size="0.011 0.005" pos="-0.026 0 0.034" quat="1 0 1 0" type="cylinder" class="plastic_collision"/>
                          <geom size="0.011 0.005" pos="0.031 0 0.034" quat="1 0 1 0" type="cylinder" class="plastic_collision"/>
                          <geom size="0.0135 0.009 0.005" pos="-0.021 0 0.011" quat="0.923879 0 0.382684 0" type="box"
                            class="plastic_collision"/>
                          <geom size="0.0135 0.009 0.005" pos="0.026 0 0.01" quat="0.923879 0 -0.382684 0" type="box"
                            class="plastic_collision"/>
                          <body name="rh_palm" pos="0 0 0.034">
                            <inertial mass="0.3" pos="0 0 0.035" quat="1 0 0 1" diaginertia="0.0005287 0.0003581 0.000191"/>
                            <joint class="wrist_x" name="rh_WRJ1"/>
                            <site name="grasp_site" pos="0 -.035 0.09" group="4"/>
                            <geom class="plastic_visual" mesh="palm"/>
                            <geom size="0.031 0.0035 0.049" pos="0.011 0.0085 0.038" type="box" class="plastic_collision"/>
                            <geom size="0.018 0.0085 0.049" pos="-0.002 -0.0035 0.038" type="box" class="plastic_collision"/>
                            <geom size="0.013 0.0085 0.005" pos="0.029 -0.0035 0.082" type="box" class="plastic_collision"/>
                            <geom size="0.013 0.007 0.009" pos="0.0265 -0.001 0.07" quat="0.987241 0.0990545 0.0124467 0.124052"
                              type="box" class="plastic_collision"/>
                            <geom size="0.0105 0.0135 0.012" pos="0.0315 -0.0085 0.001" type="box" class="plastic_collision"/>
                            <geom size="0.011 0.0025 0.015" pos="0.0125 -0.015 0.004" quat="0.971338 0 0 -0.237703" type="box"
                              class="plastic_collision"/>
                            <geom size="0.009 0.012 0.002" pos="0.011 0 0.089" type="box" class="plastic_collision"/>
                            <geom size="0.01 0.012 0.02" pos="-0.03 0 0.009" type="box" class="plastic_collision"/>
                            <body name="rh_ffknuckle" pos="0.033 0 0.095">
                              <inertial mass="0.008" pos="0 0 0" quat="0.5 0.5 -0.5 0.5" diaginertia="3.2e-07 2.6e-07 2.6e-07"/>
                              <joint name="rh_FFJ4" class="knuckle"/>
                              <geom pos="0 0 0.0005" class="plastic_visual" mesh="f_knuckle" material="metallic_hand"/>
                              <geom size="0.009 0.009" quat="1 0 1 0" type="cylinder" class="plastic_collision"/>
                              <body name="rh_ffproximal">
                                <inertial mass="0.03" pos="0 0 0.0225" quat="1 0 0 1" diaginertia="1e-05 9.8e-06 1.8e-06"/>
                                <joint name="rh_FFJ3" class="proximal"/>
                                <geom class="plastic_visual" mesh="f_proximal"/>
                                <geom size="0.009 0.02" pos="0 0 0.025" type="capsule" class="plastic_collision"/>
                                <body name="rh_ffmiddle" pos="0 0 0.045">
                                  <inertial mass="0.017" pos="0 0 0.0125" quat="1 0 0 1" diaginertia="2.7e-06 2.6e-06 8.7e-07"/>
                                  <joint name="rh_FFJ2" class="middle_distal"/>
                                  <geom class="plastic_visual" mesh="f_middle"/>
                                  <geom size="0.009 0.0125" pos="0 0 0.0125" type="capsule" class="plastic_collision"/>
                                  <body name="rh_ffdistal" pos="0 0 0.025">
                                    <inertial mass="0.013" pos="0 0 0.0130769" quat="1 0 0 1"
                                      diaginertia="1.28092e-06 1.12092e-06 5.3e-07"/>
                                    <joint name="rh_FFJ1" class="middle_distal"/>
                                    <geom class="plastic_visual" mesh="f_distal_pst"/>
                                    <geom class="plastic_collision" type="mesh" mesh="f_distal_pst"/>
                                  </body>
                                </body>
                              </body>
                            </body>
                            <body name="rh_mfknuckle" pos="0.011 0 0.099">
                              <inertial mass="0.008" pos="0 0 0" quat="0.5 0.5 -0.5 0.5" diaginertia="3.2e-07 2.6e-07 2.6e-07"/>
                              <joint name="rh_MFJ4" class="knuckle"/>
                              <geom pos="0 0 0.0005" class="plastic_visual" mesh="f_knuckle" material="metallic_hand"/>
                              <geom size="0.009 0.009" quat="1 0 1 0" type="cylinder" class="plastic_collision"/>
                              <body name="rh_mfproximal">
                                <inertial mass="0.03" pos="0 0 0.0225" quat="1 0 0 1" diaginertia="1e-05 9.8e-06 1.8e-06"/>
                                <joint name="rh_MFJ3" class="proximal"/>
                                <geom class="plastic_visual" mesh="f_proximal"/>
                                <geom size="0.009 0.02" pos="0 0 0.025" type="capsule" class="plastic_collision"/>
                                <body name="rh_mfmiddle" pos="0 0 0.045">
                                  <inertial mass="0.017" pos="0 0 0.0125" quat="1 0 0 1" diaginertia="2.7e-06 2.6e-06 8.7e-07"/>
                                  <joint name="rh_MFJ2" class="middle_distal"/>
                                  <geom class="plastic_visual" mesh="f_middle"/>
                                  <geom size="0.009 0.0125" pos="0 0 0.0125" type="capsule" class="plastic_collision"/>
                                  <body name="rh_mfdistal" pos="0 0 0.025">
                                    <inertial mass="0.013" pos="0 0 0.0130769" quat="1 0 0 1"
                                      diaginertia="1.28092e-06 1.12092e-06 5.3e-07"/>
                                    <joint name="rh_MFJ1" class="middle_distal"/>
                                    <geom class="plastic_visual" mesh="f_distal_pst"/>
                                    <geom class="plastic_collision" type="mesh" mesh="f_distal_pst"/>
                                  </body>
                                </body>
                              </body>
                            </body>
                            <body name="rh_rfknuckle" pos="-0.011 0 0.095">
                              <inertial mass="0.008" pos="0 0 0" quat="0.5 0.5 -0.5 0.5" diaginertia="3.2e-07 2.6e-07 2.6e-07"/>
                              <joint name="rh_RFJ4" class="knuckle" axis="0 1 0"/>
                              <geom pos="0 0 0.0005" class="plastic_visual" mesh="f_knuckle" material="metallic_hand"/>
                              <geom size="0.009 0.009" quat="1 0 1 0" type="cylinder" class="plastic_collision"/>
                              <body name="rh_rfproximal">
                                <inertial mass="0.03" pos="0 0 0.0225" quat="1 0 0 1" diaginertia="1e-05 9.8e-06 1.8e-06"/>
                                <joint name="rh_RFJ3" class="proximal"/>
                                <geom class="plastic_visual" mesh="f_proximal"/>
                                <geom size="0.009 0.02" pos="0 0 0.025" type="capsule" class="plastic_collision"/>
                                <body name="rh_rfmiddle" pos="0 0 0.045">
                                  <inertial mass="0.017" pos="0 0 0.0125" quat="1 0 0 1" diaginertia="2.7e-06 2.6e-06 8.7e-07"/>
                                  <joint name="rh_RFJ2" class="middle_distal"/>
                                  <geom class="plastic_visual" mesh="f_middle"/>
                                  <geom size="0.009 0.0125" pos="0 0 0.0125" type="capsule" class="plastic_collision"/>
                                  <body name="rh_rfdistal" pos="0 0 0.025">
                                    <inertial mass="0.013" pos="0 0 0.0130769" quat="1 0 0 1"
                                      diaginertia="1.28092e-06 1.12092e-06 5.3e-07"/>
                                    <joint name="rh_RFJ1" class="middle_distal"/>
                                    <geom class="plastic_visual" mesh="f_distal_pst"/>
                                    <geom class="plastic_collision" type="mesh" mesh="f_distal_pst"/>
                                  </body>
                                </body>
                              </body>
                            </body>
                            <body name="rh_lfmetacarpal" pos="-0.033 0 0.02071">
                              <inertial mass="0.03" pos="0 0 0.04" quat="1 0 0 1" diaginertia="1.638e-05 1.45e-05 4.272e-06"/>
                              <joint name="rh_LFJ5" class="metacarpal"/>
                              <geom class="plastic_visual" mesh="lf_metacarpal"/>
                              <geom size="0.011 0.012 0.025" pos="0.002 0 0.033" type="box" class="plastic_collision"/>
                              <body name="rh_lfknuckle" pos="0 0 0.06579">
                                <inertial mass="0.008" pos="0 0 0" quat="0.5 0.5 -0.5 0.5" diaginertia="3.2e-07 2.6e-07 2.6e-07"/>
                                <joint name="rh_LFJ4" class="knuckle" axis="0 1 0"/>
                                <geom pos="0 0 0.0005" class="plastic_visual" mesh="f_knuckle" material="metallic_hand"/>
                                <geom size="0.009 0.009" quat="1 0 1 0" type="cylinder" class="plastic_collision"/>
                                <body name="rh_lfproximal">
                                  <inertial mass="0.03" pos="0 0 0.0225" quat="1 0 0 1" diaginertia="1e-05 9.8e-06 1.8e-06"/>
                                  <joint name="rh_LFJ3" class="proximal"/>
                                  <geom class="plastic_visual" mesh="f_proximal"/>
                                  <geom size="0.009 0.02" pos="0 0 0.025" type="capsule" class="plastic_collision"/>
                                  <body name="rh_lfmiddle" pos="0 0 0.045">
                                    <inertial mass="0.017" pos="0 0 0.0125" quat="1 0 0 1" diaginertia="2.7e-06 2.6e-06 8.7e-07"/>
                                    <joint name="rh_LFJ2" class="middle_distal"/>
                                    <geom class="plastic_visual" mesh="f_middle"/>
                                    <geom size="0.009 0.0125" pos="0 0 0.0125" type="capsule" class="plastic_collision"/>
                                    <body name="rh_lfdistal" pos="0 0 0.025">
                                      <inertial mass="0.013" pos="0 0 0.0130769" quat="1 0 0 1"
                                        diaginertia="1.28092e-06 1.12092e-06 5.3e-07"/>
                                      <joint name="rh_LFJ1" class="middle_distal"/>
                                      <geom class="plastic_visual" mesh="f_distal_pst"/>
                                      <geom class="plastic_collision" type="mesh" mesh="f_distal_pst"/>
                                    </body>
                                  </body>
                                </body>
                              </body>
                            </body>
                            <body name="rh_thbase" pos="0.034 -0.00858 0.029" quat="0.92388 0 0.382683 0">
                              <inertial mass="0.01" pos="0 0 0" diaginertia="1.6e-07 1.6e-07 1.6e-07"/>
                              <joint name="rh_THJ5" class="thbase"/>
                              <geom class="plastic_collision" size="0.013"/>
                              <body name="rh_thproximal">
                                <inertial mass="0.04" pos="0 0 0.019" diaginertia="1.36e-05 1.36e-05 3.13e-06"/>
                                <joint name="rh_THJ4" class="thproximal"/>
                                <geom class="plastic_visual" mesh="th_proximal"/>
                                <geom class="plastic_collision" size="0.0105 0.009" pos="0 0 0.02" type="capsule"/>
                                <body name="rh_thhub" pos="0 0 0.038">
                                  <inertial mass="0.005" pos="0 0 0" diaginertia="1e-06 1e-06 3e-07"/>
                                  <joint name="rh_THJ3" class="thhub"/>
                                  <geom size="0.011" class="plastic_collision"/>
                                  <body name="rh_thmiddle">
                                    <inertial mass="0.02" pos="0 0 0.016" diaginertia="5.1e-06 5.1e-06 1.21e-06"/>
                                    <joint name="rh_THJ2" class="thmiddle"/>
                                    <geom class="plastic_visual" mesh="th_middle"/>
                                    <geom size="0.009 0.009" pos="0 0 0.012" type="capsule" class="plastic_collision"/>
                                    <geom size="0.01" pos="0 0 0.03" class="plastic_collision"/>
                                    <body name="rh_thdistal" pos="0 0 0.032" quat="1 0 0 -1">
                                      <inertial mass="0.017" pos="0 0 0.0145588" quat="1 0 0 1"
                                        diaginertia="2.37794e-06 2.27794e-06 1e-06"/>
                                      <joint name="rh_THJ1" class="thdistal"/>
                                      <geom class="plastic_visual" mesh="th_distal_pst"/>
                                      <geom class="plastic_collision" type="mesh" mesh="th_distal_pst"/>
                                    </body>
                                  </body>
                                </body>
                              </body>
                            </body>
                          </body>
                        </body>
                      </body>
                      <!-- <camera name="wrist" pos="0 -0.05639 -0.058475" quat="0 0 0 1" fovy="41.83792730009236"
                        resolution="640 480"/> -->
                      <!-- <camera name="wrist" pos="0. 0. -0.181525" quat="1.000000e+00 0.000000e+00 0.000000e+00 6.123234e-17" fovy="41.83792730009236" -->
                        <!-- resolution="640 480"/> -0.1375 -->
                      <!-- <camera name="wrist" pos="0 0. -0.22" euler="0 0 -1.57" fovy="41.83792730009236" resolution="224 224"/> -->
                      <!-- <camera name="wrist_overview"
                        pos="-0.5  0  0.7" 
                        euler="0.2  -0.5  -1.57"  
                        fovy="55"
                        resolution="640 480"/> -->
                      <site name="pinch_site" pos="0 0 -0.181525" quat="0 1 0 0"/>
                    </body>
                  </body>
                </body>
              </body>
            </body>
          </body>
        </body>
      </body>
    </body>
  </worldbody>

  <contact>
    <!-- 추가: 손가락 충돌 제외 설정 -->
    <exclude body1="rh_ffproximal" body2="rh_ffmiddle"/>
    <exclude body1="rh_ffmiddle" body2="rh_ffdistal"/>
    <exclude body1="rh_mfproximal" body2="rh_mfmiddle"/>
    <exclude body1="rh_mfmiddle" body2="rh_mfdistal"/>
    <exclude body1="rh_rfproximal" body2="rh_rfmiddle"/>
    <exclude body1="rh_rfmiddle" body2="rh_rfdistal"/>
    <exclude body1="rh_lfproximal" body2="rh_lfmiddle"/>
    <exclude body1="rh_lfmiddle" body2="rh_lfdistal"/>
    <exclude body1="rh_thproximal" body2="rh_thmiddle"/>
    <exclude body1="rh_thmiddle" body2="rh_thdistal"/>

  </contact>

  <tendon>
    <!-- 추가: right_hand tendon -->
    <fixed name="rh_FFJ0">
      <joint joint="rh_FFJ2" coef="1"/>
      <joint joint="rh_FFJ1" coef="1"/>
    </fixed>
    <fixed name="rh_MFJ0">
      <joint joint="rh_MFJ2" coef="1"/>
      <joint joint="rh_MFJ1" coef="1"/>
    </fixed>
    <fixed name="rh_RFJ0">
      <joint joint="rh_RFJ2" coef="1"/>
      <joint joint="rh_RFJ1" coef="1"/>
    </fixed>
    <fixed name="rh_LFJ0">
      <joint joint="rh_LFJ2" coef="1"/>
      <joint joint="rh_LFJ1" coef="1"/>
    </fixed>
  </tendon>

  <equality>
  </equality>

  <actuator>
    <position name="joint_x" joint="joint_x" kp="1000000" kv="50000"/>
    <position name="joint_y" joint="joint_y" kp="1000000" kv="50000"/>
    <position name="joint_th" joint="joint_th" kp="50000" kv="1000"/>

    <motor name="joint_1" joint="joint_1" gear="100" forcerange="-10000 10000"/>
    <motor name="joint_2" joint="joint_2" gear="100" forcerange="-10000 10000"/>
    <motor name="joint_3" joint="joint_3" gear="100" forcerange="-10000 10000"/>
    <motor name="joint_4" joint="joint_4" gear="100"  forcerange="-10000 10000"/>
    <motor name="joint_5" joint="joint_5" gear="100"  forcerange="-10000 10000"/>
    <motor name="joint_6" joint="joint_6" gear="100"  forcerange="-10000 10000"/>
    <motor name="joint_7" joint="joint_7" gear="100"  forcerange="-10000 10000"/>
<!-- 
    <general class="2f85" name="fingers_actuator" tendon="split" forcerange="-50 50" ctrlrange="0 255"
      gainprm="1 0 0" biasprm="0 -100 -10"/> -->

      <!-- 추가: right_hand actuator -->
    <position name="rh_A_WRJ2" joint="rh_WRJ2"/>
    <position name="rh_A_WRJ1" joint="rh_WRJ1"/>
    <position name="rh_A_THJ5" joint="rh_THJ5"/>
    <position name="rh_A_THJ4" joint="rh_THJ4"/>
    <position name="rh_A_THJ3" joint="rh_THJ3"/>
    <position name="rh_A_THJ2" joint="rh_THJ2"/>
    <position name="rh_A_THJ1" joint="rh_THJ1"/>
    <position name="rh_A_FFJ4" joint="rh_FFJ4"/>
    <position name="rh_A_FFJ3" joint="rh_FFJ3"/>
    <position name="rh_A_FFJ0" tendon="rh_FFJ0"/>
    <position name="rh_A_MFJ4" joint="rh_MFJ4"/>
    <position name="rh_A_MFJ3" joint="rh_MFJ3"/>
    <position name="rh_A_MFJ0" tendon="rh_MFJ0"/>
    <position name="rh_A_RFJ4" joint="rh_RFJ4"/>
    <position name="rh_A_RFJ3" joint="rh_RFJ3"/>
    <position name="rh_A_RFJ0" tendon="rh_RFJ0"/>
    <position name="rh_A_LFJ5" joint="rh_LFJ5"/>
    <position name="rh_A_LFJ4" joint="rh_LFJ4"/>
    <position name="rh_A_LFJ3" joint="rh_LFJ3"/>
    <position name="rh_A_LFJ0" tendon="rh_LFJ0"/>

  </actuator>

  <keyframe>
    <key name="home"
          qpos="0 0 0 1 0 0 0   0 0 0   0.26179939 3.14159265 -2.26892803 0 0.95993109 1.57079633 0   0 0 0 0 0 0 0 0 0 0 0 0 0 0 0 0 0 0 0 0 0 0 0 0"
          ctrl="0 0 0 0 0.26179939 3.14159265 -2.26892803 0 0.95993109 1.57079633 
                0 0 0 0 0 0 0 0 0 0
                0 0 0 0 0 0 0 0 0 0" />
    <key name="retract"
        qpos="0 0 0 1 0 0 0   0 0 0   -0.34906585 3.14159265 -2.54818071 0 -0.87266463 1.57079633 0  0 0 0 0 0 0 0 0 0 0 0 0 0 0 0 0 0 0 0 0 0 0 0 0"
        ctrl="0 0 0 0 -0.34906585 3.14159265 -2.54818071 0 -0.87266463 1.57079633 
                0 0 0 0 0 0 0 0 0 0
                0 0 0 0 0 0 0 0 0 0"/>
  </keyframe>

  <!-- <sensor>
    <rangefinder name="rf_00" site="rf_00" cutoff="6.0"/>
    <rangefinder name="rf_01" site="rf_01" cutoff="6.0"/>
    <rangefinder name="rf_02" site="rf_02" cutoff="6.0"/>
    <rangefinder name="rf_03" site="rf_03" cutoff="6.0"/>
    <rangefinder name="rf_04" site="rf_04" cutoff="6.0"/>
    <rangefinder name="rf_05" site="rf_05" cutoff="6.0"/>
    <rangefinder name="rf_06" site="rf_06" cutoff="6.0"/>
    <rangefinder name="rf_07" site="rf_07" cutoff="6.0"/>
    <rangefinder name="rf_08" site="rf_08" cutoff="6.0"/>
    <rangefinder name="rf_09" site="rf_09" cutoff="6.0"/>
    <rangefinder name="rf_10" site="rf_10" cutoff="6.0"/>
    <rangefinder name="rf_11" site="rf_11" cutoff="6.0"/>
    <rangefinder name="rf_12" site="rf_12" cutoff="6.0"/>
    <rangefinder name="rf_13" site="rf_13" cutoff="6.0"/>
    <rangefinder name="rf_14" site="rf_14" cutoff="6.0"/>
    <rangefinder name="rf_15" site="rf_15" cutoff="6.0"/>
    <rangefinder name="rf_16" site="rf_16" cutoff="6.0"/>
    <rangefinder name="rf_17" site="rf_17" cutoff="6.0"/>
    <rangefinder name="rf_18" site="rf_18" cutoff="6.0"/>
    <rangefinder name="rf_19" site="rf_19" cutoff="6.0"/>
    <rangefinder name="rf_20" site="rf_20" cutoff="6.0"/>
    <rangefinder name="rf_21" site="rf_21" cutoff="6.0"/>
    <rangefinder name="rf_22" site="rf_22" cutoff="6.0"/>
    <rangefinder name="rf_23" site="rf_23" cutoff="6.0"/>
    <rangefinder name="rf_24" site="rf_24" cutoff="6.0"/>
    <rangefinder name="rf_25" site="rf_25" cutoff="6.0"/>
    <rangefinder name="rf_26" site="rf_26" cutoff="6.0"/>
    <rangefinder name="rf_27" site="rf_27" cutoff="6.0"/>
    <rangefinder name="rf_28" site="rf_28" cutoff="6.0"/>
    <rangefinder name="rf_29" site="rf_29" cutoff="6.0"/>
    <rangefinder name="rf_30" site="rf_30" cutoff="6.0"/>
    <rangefinder name="rf_31" site="rf_31" cutoff="6.0"/>
    <rangefinder name="rf_32" site="rf_32" cutoff="6.0"/>
    <rangefinder name="rf_33" site="rf_33" cutoff="6.0"/>
    <rangefinder name="rf_34" site="rf_34" cutoff="6.0"/>
    <rangefinder name="rf_35" site="rf_35" cutoff="6.0"/>
    <rangefinder name="rf_36" site="rf_36" cutoff="6.0"/>
  </sensor> -->
</mujoco>
